<?xml version="1.0" ?>
<!-- =================================================================================== -->
<!-- |    This document was autogenerated by xacro from simplified.xacro               | -->
<!-- |    EDITING THIS FILE BY HAND IS RECOMMENDED                                 | -->
<!-- =================================================================================== -->
<robot name="p50l_autoconverted">
  <material name="silver_default">
    <color rgba="0.700 0.700 0.700 1.000"/>
  </material>
  <material name="Steel_Satin">
    <color rgba="0.6274509803921569 0.6274509803921569 0.6274509803921569 1.0"/>
  </material>
  <link name="root"/>
  <link name="base_link">
    <inertial>
      <origin rpy="0.0 0.0 0.0" xyz="0.00021786098818427164 0.002773869297414059 0.055149595632162526"/>
      <mass value="11.892138799732054"/>
      <inertia ixx="0.026209013399999998" ixy="-6.532699999999999e-06" ixz="-0.00023003580000000002" iyy="0.0317573509" iyz="-0.00034773710000000007" izz="0.0270765676"/>
    </inertial>
    <visual>
      <origin rpy="0.0 0.0 0.0" xyz="0.0 0.0 0.0"/>
      <geometry>
        <mesh filename="meshes/visual/base_link.stl" scale="0.001 0.001 0.001"/>
      </geometry>
      <material name="Steel_Satin"/>
    </visual>
    <collision>
      <origin rpy="0.0 0.0 0.0" xyz="0.0 0.0 0.0"/>
      <geometry>
        <mesh filename="meshes/visual/base_link.stl" scale="0.001 0.001 0.001"/>
      </geometry>
    </collision>
  </link>
  <link name="index_mcp">
    <inertial>
      <origin rpy="1.7017348928028144 0.10749161153413622 1.3962634015954638" xyz="0.003757595845050581 0.0 3.16897459018245e-05"/>
      <mass value="0.0026395511835507687"/>
      <inertia ixx="1.186e-07" ixy="-8e-10" ixz="-9.5e-09" iyy="1.138e-07" iyz="-7e-09" izz="6.7e-08"/>
    </inertial>
    <visual>
      <origin rpy="1.7017348928028144 0.10749161153413622 1.3962634015954638" xyz="-0.19251082012232146 0.06049540175647385 0.0027879270241163486"/>
      <geometry>
        <mesh filename="meshes/visual/index_mcp.stl" scale="0.001 0.001 0.001"/>
      </geometry>
      <material name="Steel_Satin"/>
    </visual>
    <collision>
      <origin rpy="1.7017348928028144 0.10749161153413622 1.3962634015954638" xyz="-0.19251082012232146 0.06049540175647385 0.0027879270241163486"/>
      <geometry>
        <mesh filename="meshes/visual/index_mcp.stl" scale="0.001 0.001 0.001"/>
      </geometry>
    </collision>
  </link>
  <link name="middle_mcp">
    <inertial>
      <origin rpy="1.710422666954546 0.0 1.256637061435917" xyz="0.0037575958450509006 0.0 3.168974590182283e-05"/>
      <mass value="0.0026395511835507687"/>
      <inertia ixx="1.15e-07" ixy="-2.2000000000000003e-09" ixz="-1.63e-08" iyy="1.1399999999999999e-07" iyz="-5.9e-09" izz="7.040000000000001e-08"/>
    </inertial>
    <visual>
      <origin rpy="1.710422666954546 0.0 1.256637061435917" xyz="-0.19275971829860722 0.06552295023217881 0.005739211794065033"/>
      <geometry>
        <mesh filename="meshes/visual/middle_mcp.stl" scale="0.001 0.001 0.001"/>
      </geometry>
      <material name="Steel_Satin"/>
    </visual>
    <collision>
      <origin rpy="1.710422666954546 0.0 1.256637061435917" xyz="-0.19275971829860722 0.06552295023217881 0.005739211794065033"/>
      <geometry>
        <mesh filename="meshes/visual/middle_mcp.stl" scale="0.001 0.001 0.001"/>
      </geometry>
    </collision>
  </link>
  <link name="pinky_mcp">
    <inertial>
      <origin rpy="1.7010466700342675 -0.20431604263360326 0.9948376736367678" xyz="0.0037575958450507233 0.0 -0.00011831025409817731"/>
      <mass value="0.0026395511835507687"/>
      <inertia ixx="1.042e-07" ixy="-9e-10" ixz="-2.5099999999999996e-08" iyy="1.151e-07" iyz="1e-09" izz="8.01e-08"/>
    </inertial>
    <visual>
      <origin rpy="1.7010466700342675 -0.20431604263360326 0.9948376736367678" xyz="-0.17443999513816394 0.0646356315813313 0.0019507069049774773"/>
      <geometry>
        <mesh filename="meshes/visual/pinky_mcp.stl" scale="0.001 0.001 0.001"/>
      </geometry>
      <material name="Steel_Satin"/>
    </visual>
    <collision>
      <origin rpy="1.7010466700342675 -0.20431604263360326 0.9948376736367678" xyz="-0.17443999513816394 0.0646356315813313 0.0019507069049774773"/>
      <geometry>
        <mesh filename="meshes/visual/pinky_mcp.stl" scale="0.001 0.001 0.001"/>
      </geometry>
    </collision>
  </link>
  <link name="ring_mcp">
    <inertial>
      <origin rpy="1.7018668462741051 -0.10862308449673952 1.1519173063162567" xyz="0.003757595845050865 0.0 -0.00011831025409819562"/>
      <mass value="0.0026395511835507687"/>
      <inertia ixx="1.1110000000000001e-07" ixy="-2.2000000000000003e-09" ixz="-2.0600000000000002e-08" iyy="1.1460000000000002e-07" iyz="-2.9000000000000003e-09" izz="7.36e-08"/>
    </inertial>
    <visual>
      <origin rpy="1.7018668462741051 -0.10862308449673952 1.1519173063162567" xyz="-0.18688688454912455 0.061034394923213525 0.0033431266067439664"/>
      <geometry>
        <mesh filename="meshes/visual/ring_mcp.stl" scale="0.001 0.001 0.001"/>
      </geometry>
      <material name="Steel_Satin"/>
    </visual>
    <collision>
      <origin rpy="1.7018668462741051 -0.10862308449673952 1.1519173063162567" xyz="-0.18688688454912455 0.061034394923213525 0.0033431266067439664"/>
      <geometry>
        <mesh filename="meshes/visual/ring_mcp.stl" scale="0.001 0.001 0.001"/>
      </geometry>
    </collision>
  </link>
  <link name="thumb_cmc">
    <inertial>
      <origin rpy="1.747900959674252 -1.160349575471347 -2.234127698528688" xyz="-6.286223667597568e-06 0.0005149645697526762 -0.003273089943228995"/>
      <mass value="0.13646099304190434"/>
      <inertia ixx="1.92542e-05" ixy="1.1488e-06" ixz="1.3239e-06" iyy="1.46583e-05" iyz="-3.821e-06" izz="1.97712e-05"/>
    </inertial>
    <visual>
      <origin rpy="1.747900959674252 -1.160349575471347 -2.234127698528688" xyz="0.12438495858597946 -0.07468043221942657 0.028859361053467456"/>
      <geometry>
        <mesh filename="meshes/visual/thumb_cmc.stl" scale="0.001 0.001 0.001"/>
      </geometry>
      <material name="Steel_Satin"/>
    </visual>
    <collision>
      <origin rpy="1.747900959674252 -1.160349575471347 -2.234127698528688" xyz="0.12438495858597946 -0.07468043221942657 0.028859361053467456"/>
      <geometry>
        <mesh filename="meshes/visual/thumb_cmc.stl" scale="0.001 0.001 0.001"/>
      </geometry>
    </collision>
  </link>
  <link name="index_pp">
    <inertial>
      <origin rpy="2.0499412441925933 0.16055192522689543 1.4432748244642735" xyz="0.018561009678868496 -4.811339238131041e-10 0.001514164977491612"/>
      <mass value="0.011897317640220903"/>
      <inertia ixx="2.1826e-06" ixy="-1.0820000000000002e-07" ixz="-1.565e-07" iyy="1.9537e-06" iyz="-6.798000000000001e-07" izz="1.0794e-06"/>
    </inertial>
    <visual>
      <origin rpy="2.0499412441925933 0.16055192522689543 1.4432748244642735" xyz="-0.18840470347709237 0.06049540175647402 0.07154055403176121"/>
      <geometry>
        <mesh filename="meshes/visual/index_pp.stl" scale="0.001 0.001 0.001"/>
      </geometry>
      <material name="Steel_Satin"/>
    </visual>
    <collision>
      <origin rpy="2.0499412441925933 0.16055192522689543 1.4432748244642735" xyz="-0.18840470347709237 0.06049540175647402 0.07154055403176121"/>
      <geometry>
        <mesh filename="meshes/visual/index_pp.stl" scale="0.001 0.001 0.001"/>
      </geometry>
    </collision>
  </link>
  <link name="thumb_mp">
    <inertial>
      <origin rpy="-2.446530361523002 -1.1678650691047197 2.0357287662177264" xyz="0.0011454089615110697 -0.0003310968932721936 -0.017558796858869564"/>
      <mass value="0.13554186470832574"/>
      <inertia ixx="1.89377e-05" ixy="3.6814e-06" ixz="5.1552e-06" iyy="3.06259e-05" iyz="5.782e-07" izz="2.40837e-05"/>
    </inertial>
    <visual>
      <origin rpy="-2.446530361523002 -1.1678650691047197 2.0357287662177264" xyz="0.12851644713633875 -0.033521944510498315 0.06873471100953825"/>
      <geometry>
        <mesh filename="meshes/visual/thumb_mp.stl" scale="0.001 0.001 0.001"/>
      </geometry>
      <material name="Steel_Satin"/>
    </visual>
    <collision>
      <origin rpy="-2.446530361523002 -1.1678650691047197 2.0357287662177264" xyz="0.12851644713633875 -0.033521944510498315 0.06873471100953825"/>
      <geometry>
        <mesh filename="meshes/visual/thumb_mp.stl" scale="0.001 0.001 0.001"/>
      </geometry>
    </collision>
  </link>
  <link name="middle_pp">
    <inertial>
      <origin rpy="2.0436691263374853 0.10588779879323651 1.2744617278205952" xyz="0.020018862469634583 -4.505783479658021e-10 0.0014936913701926002"/>
      <mass value="0.012870595232919467"/>
      <inertia ixx="2.4711e-06" ixy="-2.674e-07" ixz="-4.5450000000000005e-07" iyy="2.3213e-06" iyz="-7.877000000000001e-07" izz="1.3277000000000002e-06"/>
    </inertial>
    <visual>
      <origin rpy="2.0436691263374853 0.10588779879323651 1.2744617278205952" xyz="-0.1876291924166628 0.06552295023217902 0.07439898274184686"/>
      <geometry>
        <mesh filename="meshes/visual/middle_pp.stl" scale="0.001 0.001 0.001"/>
      </geometry>
      <material name="Steel_Satin"/>
    </visual>
    <collision>
      <origin rpy="2.0436691263374853 0.10588779879323651 1.2744617278205952" xyz="-0.1876291924166628 0.06552295023217902 0.07439898274184686"/>
      <geometry>
        <mesh filename="meshes/visual/middle_pp.stl" scale="0.001 0.001 0.001"/>
      </geometry>
    </collision>
  </link>
  <link name="pinky_pp">
    <inertial>
      <origin rpy="1.9919857950196116 -0.008258409274978895 0.963605760521225" xyz="0.016832793550349265 -5.251937995609524e-10 0.0015430211276084194"/>
      <mass value="0.010734968037856127"/>
      <inertia ixx="1.3951e-06" ixy="-2.167e-07" ixz="-4.893e-07" iyy="1.74e-06" iyz="-3.312e-07" izz="1.1441e-06"/>
    </inertial>
    <visual>
      <origin rpy="1.9919857950196116 -0.008258409274978895 0.963605760521225" xyz="-0.1716587257116102 0.06463563158133125 0.06471419220585617"/>
      <geometry>
        <mesh filename="meshes/visual/pinky_pp.stl" scale="0.001 0.001 0.001"/>
      </geometry>
      <material name="Steel_Satin"/>
    </visual>
    <collision>
      <origin rpy="1.9919857950196116 -0.008258409274978895 0.963605760521225" xyz="-0.1716587257116102 0.06463563158133125 0.06471419220585617"/>
      <geometry>
        <mesh filename="meshes/visual/pinky_pp.stl" scale="0.001 0.001 0.001"/>
      </geometry>
    </collision>
  </link>
  <link name="ring_pp">
    <inertial>
      <origin rpy="2.019857285927789 0.03642859332491177 1.140313153171244" xyz="0.018561009678868496 -4.811339060495356e-10 0.0015141649774915945"/>
      <mass value="0.011897317640220903"/>
      <inertia ixx="1.9394000000000004e-06" ixy="-2.636e-07" ixz="-5.119e-07" iyy="2.0494000000000002e-06" iyz="-5.537000000000001e-07" izz="1.2269e-06"/>
    </inertial>
    <visual>
      <origin rpy="2.019857285927789 0.03642859332491177 1.140313153171244" xyz="-0.18287874025686066 0.06103439492321343 0.07027972562493867"/>
      <geometry>
        <mesh filename="meshes/visual/ring_pp.stl" scale="0.001 0.001 0.001"/>
      </geometry>
      <material name="Steel_Satin"/>
    </visual>
    <collision>
      <origin rpy="2.019857285927789 0.03642859332491177 1.140313153171244" xyz="-0.18287874025686066 0.06103439492321343 0.07027972562493867"/>
      <geometry>
        <mesh filename="meshes/visual/ring_pp.stl" scale="0.001 0.001 0.001"/>
      </geometry>
    </collision>
  </link>
  <link name="middle_mp">
    <inertial>
      <origin rpy="2.3839619508322665 0.1999622112545527 1.326850468483252" xyz="0.015462347933960601 0.0 0.0005268185283266114"/>
      <mass value="0.006850263254868857"/>
      <inertia ixx="7.458000000000001e-07" ixy="-9.640000000000002e-08" ixz="-8.12e-08" iyy="4.819000000000001e-07" iyz="-2.581e-07" izz="5.603000000000001e-07"/>
    </inertial>
    <visual>
      <origin rpy="2.3839619508322665 0.1999622112545527 1.326850468483252" xyz="-0.19067692703364025 0.06552295023217883 0.14751029175781"/>
      <geometry>
        <mesh filename="meshes/visual/middle_mp.stl" scale="0.001 0.001 0.001"/>
      </geometry>
      <material name="Steel_Satin"/>
    </visual>
    <collision>
      <origin rpy="2.3839619508322665 0.1999622112545527 1.326850468483252" xyz="-0.19067692703364025 0.06552295023217883 0.14751029175781"/>
      <geometry>
        <mesh filename="meshes/visual/middle_mp.stl" scale="0.001 0.001 0.001"/>
      </geometry>
    </collision>
  </link>
  <link name="pinky_mp">
    <inertial>
      <origin rpy="2.2819836907453794 0.1884910856747477 0.9900145615595569" xyz="0.012255335613894688 0.0 0.0006277124921956201"/>
      <mass value="0.005213101795055971"/>
      <inertia ixx="3.716e-07" ixy="-9.810000000000001e-08" ixz="-8.86e-08" iyy="3.434e-07" iyz="-1.035e-07" izz="3.6340000000000004e-07"/>
    </inertial>
    <visual>
      <origin rpy="2.2819836907453794 0.1884910856747477 0.9900145615595569" xyz="-0.17287398873248588 0.06463563158133126 0.1307242133142259"/>
      <geometry>
        <mesh filename="meshes/visual/pinky_mp.stl" scale="0.001 0.001 0.001"/>
      </geometry>
      <material name="Steel_Satin"/>
    </visual>
    <collision>
      <origin rpy="2.2819836907453794 0.1884910856747477 0.9900145615595569" xyz="-0.17287398873248588 0.06463563158133126 0.1307242133142259"/>
      <geometry>
        <mesh filename="meshes/visual/pinky_mp.stl" scale="0.001 0.001 0.001"/>
      </geometry>
    </collision>
  </link>
  <link name="thumb_pp">
    <inertial>
      <origin rpy="-1.089745389740744 -1.1253353688103196 0.7684082760965902" xyz="0.00047431249534163556 -4.9851246354823966e-05 -0.014037341494746572"/>
      <mass value="0.08561101056611903"/>
      <inertia ixx="7.876200000000001e-06" ixy="1.8488000000000002e-06" ixz="-1.3738e-06" iyy="1.11943e-05" iyz="2.56e-07" izz="1.28189e-05"/>
    </inertial>
    <visual>
      <origin rpy="-1.089745389740744 -1.1253353688103196 0.7684082760965902" xyz="0.16260298040793872 -0.03710458352286788 0.024178686024917097"/>
      <geometry>
        <mesh filename="meshes/visual/thumb_pp.stl" scale="0.001 0.001 0.001"/>
      </geometry>
      <material name="Steel_Satin"/>
    </visual>
    <collision>
      <origin rpy="-1.089745389740744 -1.1253353688103196 0.7684082760965902" xyz="0.16260298040793872 -0.03710458352286788 0.024178686024917097"/>
      <geometry>
        <mesh filename="meshes/visual/thumb_pp.stl" scale="0.001 0.001 0.001"/>
      </geometry>
    </collision>
  </link>
  <link name="ring_mp">
    <inertial>
      <origin rpy="2.341150342426479 0.17779302730288382 1.1750431438259699" xyz="0.014231615723840392 0.0 0.000556808598009706"/>
      <mass value="0.006227568575151113"/>
      <inertia ixx="5.763e-07" ixy="-1.142e-07" ixz="-1.0070000000000002e-07" iyy="4.3380000000000003e-07" iyz="-1.8640000000000003e-07" izz="4.765e-07"/>
    </inertial>
    <visual>
      <origin rpy="2.341150342426479 0.17779302730288382 1.1750431438259699" xyz="-0.18480275324084122 0.061034394923213456 0.14098864548339793"/>
      <geometry>
        <mesh filename="meshes/visual/ring_mp.stl" scale="0.001 0.001 0.001"/>
      </geometry>
      <material name="Steel_Satin"/>
    </visual>
    <collision>
      <origin rpy="2.341150342426479 0.17779302730288382 1.1750431438259699" xyz="-0.18480275324084122 0.061034394923213456 0.14098864548339793"/>
      <geometry>
        <mesh filename="meshes/visual/ring_mp.stl" scale="0.001 0.001 0.001"/>
      </geometry>
    </collision>
  </link>
  <link name="index_mp">
    <inertial>
      <origin rpy="2.402983958242408 0.19438131835494854 1.5062434801901834" xyz="0.014231615723840392 0.0 0.0005568085980097592"/>
      <mass value="0.006227568575151113"/>
      <inertia ixx="6.37e-07" ixy="-2.11e-08" ixz="-1.7600000000000002e-08" iyy="3.994e-07" iyz="-2.1649999999999999e-07" izz="4.502e-07"/>
    </inertial>
    <visual>
      <origin rpy="2.402983958242408 0.19438131835494854 1.5062434801901834" xyz="-0.18956423138921633 0.06049540175647388 0.14406342736596212"/>
      <geometry>
        <mesh filename="meshes/visual/index_mp.stl" scale="0.001 0.001 0.001"/>
      </geometry>
      <material name="Steel_Satin"/>
    </visual>
    <collision>
      <origin rpy="2.402983958242408 0.19438131835494854 1.5062434801901834" xyz="-0.18956423138921633 0.06049540175647388 0.14406342736596212"/>
      <geometry>
        <mesh filename="meshes/visual/index_mp.stl" scale="0.001 0.001 0.001"/>
      </geometry>
    </collision>
  </link>
  <link name="pinky_dp">
    <inertial>
      <origin rpy="2.593541832501331 0.3687092547665103 1.076693635593774" xyz="0.010893060864278308 1.1616756445675947e-10 0.0008705848933307437"/>
      <mass value="0.004531952355822714"/>
      <inertia ixx="3.0200000000000003e-07" ixy="-6.46e-08" ixz="-5.3e-09" iyy="2.064e-07" iyz="-4.8000000000000006e-08" izz="3.3800000000000004e-07"/>
    </inertial>
    <visual>
      <origin rpy="2.593541832501331 0.3687092547665103 1.076693635593774" xyz="-0.14123041288352395 0.0646356315813313 0.19051746859612756"/>
      <geometry>
        <mesh filename="meshes/visual/pinky_dp.stl" scale="0.001 0.001 0.001"/>
      </geometry>
      <material name="Steel_Satin"/>
    </visual>
    <collision>
      <origin rpy="2.593541832501331 0.3687092547665103 1.076693635593774" xyz="-0.14123041288352395 0.0646356315813313 0.19051746859612756"/>
      <geometry>
        <mesh filename="meshes/visual/pinky_dp.stl" scale="0.001 0.001 0.001"/>
      </geometry>
    </collision>
  </link>
  <link name="index_dp">
    <inertial>
      <origin rpy="2.7590364373595007 0.20458224449313933 1.5775250294833583" xyz="0.010929353372684485 2.959357978848942e-07 0.0009004211113701288"/>
      <mass value="0.004517050419432207"/>
      <inertia ixx="3.239e-07" ixy="1.4000000000000001e-09" ixz="7.700000000000001e-09" iyy="1.7860000000000002e-07" iyz="-5.6e-08" izz="3.3860000000000003e-07"/>
    </inertial>
    <visual>
      <origin rpy="2.7590364373595007 0.20458224449313933 1.5775250294833583" xyz="-0.15611060132849716 0.06049540175647383 0.21012870936652572"/>
      <geometry>
        <mesh filename="meshes/visual/index_dp.stl" scale="0.001 0.001 0.001"/>
      </geometry>
      <material name="Steel_Satin"/>
    </visual>
    <collision>
      <origin rpy="2.7590364373595007 0.20458224449313933 1.5775250294833583" xyz="-0.15611060132849716 0.06049540175647383 0.21012870936652572"/>
      <geometry>
        <mesh filename="meshes/visual/index_dp.stl" scale="0.001 0.001 0.001"/>
      </geometry>
    </collision>
  </link>
  <link name="ring_dp">
    <inertial>
      <origin rpy="2.677862559213412 0.3004639944108862 1.2556655856170327" xyz="0.01092935337268445 2.959357978493671e-07 0.0009004211113698447"/>
      <mass value="0.004517050419432207"/>
      <inertia ixx="3.142e-07" ixy="-4.45e-08" ixz="-2.2000000000000003e-09" iyy="1.8940000000000002e-07" iyz="-5.19e-08" izz="3.375e-07"/>
    </inertial>
    <visual>
      <origin rpy="2.677862559213412 0.3004639944108862 1.2556655856170327" xyz="-0.1526879127886051 0.06103439492321337 0.20561083808220432"/>
      <geometry>
        <mesh filename="meshes/visual/ring_dp.stl" scale="0.001 0.001 0.001"/>
      </geometry>
      <material name="Steel_Satin"/>
    </visual>
    <collision>
      <origin rpy="2.677862559213412 0.3004639944108862 1.2556655856170327" xyz="-0.1526879127886051 0.06103439492321337 0.20561083808220432"/>
      <geometry>
        <mesh filename="meshes/visual/ring_dp.stl" scale="0.001 0.001 0.001"/>
      </geometry>
    </collision>
  </link>
  <link name="thumb_dp">
    <inertial>
      <origin rpy="-0.5657191855510028 -0.6985501890607851 0.3410946728225852" xyz="0.0008304358993063232 -9.48327541670313e-05 -0.011994918369585883"/>
      <mass value="0.05558786060995697"/>
      <inertia ixx="4.2789e-06" ixy="6.912e-07" ixz="-1.4033000000000002e-06" iyy="4.6252e-06" iyz="8.619000000000001e-07" izz="3.8414999999999996e-06"/>
    </inertial>
    <visual>
      <origin rpy="-0.5657191855510028 -0.6985501890607851 0.3410946728225852" xyz="0.16797776915732499 -0.037669496584086526 -0.03500921083680894"/>
      <geometry>
        <mesh filename="meshes/visual/thumb_dp.stl" scale="0.001 0.001 0.001"/>
      </geometry>
      <material name="Steel_Satin"/>
    </visual>
    <collision>
      <origin rpy="-0.5657191855510028 -0.6985501890607851 0.3410946728225852" xyz="0.16797776915732499 -0.037669496584086526 -0.03500921083680894"/>
      <geometry>
        <mesh filename="meshes/visual/thumb_dp.stl" scale="0.001 0.001 0.001"/>
      </geometry>
    </collision>
  </link>
  <link name="middle_dp">
    <inertial>
      <origin rpy="2.735623021869149 0.2709185204562192 1.409743541406058" xyz="0.010952231529227738 7.231160292775485e-10 0.0009189466335335083"/>
      <mass value="0.0045069103448089716"/>
      <inertia ixx="3.214e-07" ixy="-2.3300000000000003e-08" ixz="2.9000000000000003e-09" iyy="1.7840000000000004e-07" iyz="-5.2200000000000004e-08" izz="3.3769999999999996e-07"/>
    </inertial>
    <visual>
      <origin rpy="2.735623021869149 0.2709185204562192 1.409743541406058" xyz="-0.15832652771338337 0.06552295023217879 0.21460331708249272"/>
      <geometry>
        <mesh filename="meshes/visual/middle_dp.stl" scale="0.001 0.001 0.001"/>
      </geometry>
      <material name="Steel_Satin"/>
    </visual>
    <collision>
      <origin rpy="2.735623021869149 0.2709185204562192 1.409743541406058" xyz="-0.15832652771338337 0.06552295023217879 0.21460331708249272"/>
      <geometry>
        <mesh filename="meshes/visual/middle_dp.stl" scale="0.001 0.001 0.001"/>
      </geometry>
    </collision>
  </link>
  <link name="thumb_fingertip">
    <inertial>
      <origin rpy="0.07336084956952293 0.7627723998296232 -1.096455325457411" xyz="0.0 0.0 0.0"/>
      <mass value="6.165375582669709e-09"/>
      <inertia ixx="0.0" ixy="-0.0" ixz="-0.0" iyy="0.0" iyz="0.0" izz="0.0"/>
    </inertial>
    <visual>
      <origin rpy="0.07336084956952293 0.7627723998296232 -1.096455325457411" xyz="-0.019904681067230694 0.008009210836808911 -0.1727951039520778"/>
      <geometry>
        <mesh filename="meshes/visual/thumb_fingertip.stl" scale="0.001 0.001 0.001"/>
      </geometry>
      <material name="Steel_Satin"/>
    </visual>
    <collision>
      <origin rpy="0.07336084956952293 0.7627723998296232 -1.096455325457411" xyz="-0.019904681067230694 0.008009210836808911 -0.1727951039520778"/>
      <geometry>
        <mesh filename="meshes/visual/thumb_fingertip.stl" scale="0.001 0.001 0.001"/>
      </geometry>
    </collision>
  </link>
  <link name="middle_fingertip">
    <inertial>
      <origin rpy="-0.4059696317206444 -0.27091852045621967 0.1610527853888376" xyz="0.0 0.0 0.0"/>
      <mass value="6.165375582669709e-09"/>
      <inertia ixx="0.0" ixy="0.0" ixz="0.0" iyy="0.0" iyz="0.0" izz="0.0"/>
    </inertial>
    <visual>
      <origin rpy="-0.4059696317206444 -0.27091852045621967 0.1610527853888376" xyz="0.06552295023217894 -0.17732652771338356 -0.21960331708249275"/>
      <geometry>
        <mesh filename="meshes/visual/middle_fingertip.stl" scale="0.001 0.001 0.001"/>
      </geometry>
      <material name="Steel_Satin"/>
    </visual>
    <collision>
      <origin rpy="-0.4059696317206444 -0.27091852045621967 0.1610527853888376" xyz="0.06552295023217894 -0.17732652771338356 -0.21960331708249275"/>
      <geometry>
        <mesh filename="meshes/visual/middle_fingertip.stl" scale="0.001 0.001 0.001"/>
      </geometry>
    </collision>
  </link>
  <link name="ring_fingertip">
    <inertial>
      <origin rpy="-0.4637300943763816 -0.3004639944108862 0.31513074117786466" xyz="0.0 0.0 0.0"/>
      <mass value="6.165375582669709e-09"/>
      <inertia ixx="0.0" ixy="0.0" ixz="0.0" iyy="0.0" iyz="0.0" izz="0.0"/>
    </inertial>
    <visual>
      <origin rpy="-0.4637300943763816 -0.3004639944108862 0.31513074117786466" xyz="0.0610343949232135 -0.1716879127886049 -0.21061083808220407"/>
      <geometry>
        <mesh filename="meshes/visual/ring_fingertip.stl" scale="0.001 0.001 0.001"/>
      </geometry>
      <material name="Steel_Satin"/>
    </visual>
    <collision>
      <origin rpy="-0.4637300943763816 -0.3004639944108862 0.31513074117786466" xyz="0.0610343949232135 -0.1716879127886049 -0.21061083808220407"/>
      <geometry>
        <mesh filename="meshes/visual/ring_fingertip.stl" scale="0.001 0.001 0.001"/>
      </geometry>
    </collision>
  </link>
  <link name="pinky_fingertip">
    <inertial>
      <origin rpy="-0.548050821088462 -0.36870925476651006 0.4941026912011229" xyz="0.0 0.0 0.0"/>
      <mass value="6.165375582669709e-09"/>
      <inertia ixx="0.0" ixy="0.0" ixz="0.0" iyy="0.0" iyz="0.0" izz="0.0"/>
    </inertial>
    <visual>
      <origin rpy="-0.548050821088462 -0.36870925476651006 0.4941026912011229" xyz="0.0646356315813314 -0.160230412883524 -0.19551746859612745"/>
      <geometry>
        <mesh filename="meshes/visual/pinky_fingertip.stl" scale="0.001 0.001 0.001"/>
      </geometry>
      <material name="Steel_Satin"/>
    </visual>
    <collision>
      <origin rpy="-0.548050821088462 -0.36870925476651006 0.4941026912011229" xyz="0.0646356315813314 -0.160230412883524 -0.19551746859612745"/>
      <geometry>
        <mesh filename="meshes/visual/pinky_fingertip.stl" scale="0.001 0.001 0.001"/>
      </geometry>
    </collision>
  </link>
  <link name="index_fingertip">
    <inertial>
      <origin rpy="-0.3825562162302918 -0.20458224449313933 -0.006728702688461985" xyz="0.0 0.0 0.0"/>
      <mass value="6.165375582669709e-09"/>
      <inertia ixx="0.0" ixy="0.0" ixz="0.0" iyy="0.0" iyz="0.0" izz="0.0"/>
    </inertial>
    <visual>
      <origin rpy="-0.3825562162302918 -0.20458224449313933 -0.006728702688461985" xyz="0.06049540175647385 -0.1751106013284969 -0.21512870936652526"/>
      <geometry>
        <mesh filename="meshes/visual/index_fingertip.stl" scale="0.001 0.001 0.001"/>
      </geometry>
      <material name="Steel_Satin"/>
    </visual>
    <collision>
      <origin rpy="-0.3825562162302918 -0.20458224449313933 -0.006728702688461985" xyz="0.06049540175647385 -0.1751106013284969 -0.21512870936652526"/>
      <geometry>
        <mesh filename="meshes/visual/index_fingertip.stl" scale="0.001 0.001 0.001"/>
      </geometry>
    </collision>
  </link>
  <joint name="root2base" type="fixed">
    <parent link="root"/>
    <child link="base_link"/>
  </joint>
  <joint name="thumb_base2cmc" type="revolute">
    <origin rpy="1.7165715862952622 1.065626150328653 2.1032839197886477" xyz="-0.0193816495620972 -0.0019835893940246233 0.14663582315620716"/>
    <parent link="base_link"/>
    <child link="thumb_cmc"/>
    <axis xyz="0.0 1.0 0.0"/>
    <limit effort="100.0" lower="0.0" upper="1.4835298641951802" velocity="100.0"/>
  </joint>
  <joint name="thumb_cmc2mcp" type="revolute">
    <origin rpy="0.6954281481356812 -0.06724025795674526 -0.02437854694500874" xyz="0.0 -0.0018499999997562357 -0.011000000000000001"/>
    <parent link="thumb_cmc"/>
    <child link="thumb_mp"/>
    <axis xyz="0.9945218953682724 -0.10452846326765325 0.0"/>
    <limit effort="100.0" lower="-1.2217304763960306" upper="0.0" velocity="100.0"/>
  </joint>
  <joint name="thumb_mcp2pp" type="revolute">
    <origin rpy="-0.06027643041747259 -0.5204388675801157 0.016053508633057722" xyz="0.0 0.0 -0.035"/>
    <parent link="thumb_mp"/>
    <child link="thumb_pp"/>
    <axis xyz="0.10452846326765355 0.9945218953682754 0.0"/>
    <limit effort="100.0" lower="0.0" upper="1.7453292519943295" velocity="100.0"/>
  </joint>
  <joint name="thumb_pp2dp_actuated" type="revolute">
    <origin rpy="-0.06027643041747284 -0.520438867580115 0.016053508633057507" xyz="0.0 0.0 -0.031"/>
    <parent link="thumb_pp"/>
    <child link="thumb_dp"/>
    <axis xyz="0.1045284632676533 0.9945218953682702 0.0"/>
    <limit effort="100.0" lower="0.0" upper="2.0943951023931953" velocity="100.0"/>
  </joint>
  <joint name="index_base2mcp" type="revolute">
    <origin rpy="-2.1802276114930805 -1.3420224612401817 0.7055101740980305" xyz="-0.025697172830483745 0.02059554669732952 0.199106405722408"/>
    <parent link="base_link"/>
    <child link="index_mcp"/>
    <axis xyz="0.0 0.0 -1.0"/>
    <limit effort="100.0" lower="0.0" upper="0.6283185307179586" velocity="100.0"/>
  </joint>
  <joint name="index_mcp2pp" type="revolute">
    <origin xyz="0.009000000000000001 0.0 0.0" rpy="0.0 -0.34906585039886684 0.0" />
    <parent link="index_mcp" />
    <child link="index_pp" />
    <axis xyz="0.0 1.0 0.0" />
    <limit upper="1.8151424220741028" lower="0.0" effort="100.0" velocity="100.0" />
  </joint>
  <joint name="index_pp2mp" type="revolute">
    <origin rpy="0.0 -0.34906585039886484 0.0" xyz="0.039 0.0 0.001"/>
    <parent link="index_pp"/>
    <child link="index_mp"/>
    <axis xyz="0.0 1.0 0.0"/>
    <limit effort="100.0" lower="0.0" upper="1.8151424220741028" velocity="100.0"/>
  </joint>
  <joint name="index_mp2dp" type="revolute">
    <origin rpy="0.0 -0.34906585039886595 0.0" xyz="0.029 0.0 0.0"/>
    <parent link="index_mp"/>
    <child link="index_dp"/>
    <axis xyz="0.0 1.0 0.0"/>
    <limit effort="100.0" lower="0.0" upper="1.8151424220741028" velocity="100.0"/>
  </joint>
  <joint name="middle_base2mcp" type="revolute">
    <origin rpy="-1.9976345056314653 -1.2279478135732096 0.4046884465088101" xyz="-0.002749999999999559 0.022648540210313088 0.20239067588218093"/>
    <parent link="base_link"/>
    <child link="middle_mcp"/>
    <axis xyz="0.0 0.0 -1.0"/>
    <limit effort="100.0" lower="0.0" upper="0.6283185307179586" velocity="100.0"/>
  </joint>
  <joint name="middle_mcp2pp" type="revolute">
    <origin rpy="0.0 -0.3490658503988664 0.0" xyz="0.009000000000000001 0.0 0.0"/>
    <parent link="middle_mcp"/>
    <child link="middle_pp"/>
    <axis xyz="0.0 1.0 0.0"/>
    <limit effort="100.0" lower="0.0" upper="1.8151424220741028" velocity="100.0"/>
  </joint>
  <joint name="middle_pp2mp" type="revolute">
    <origin rpy="0.0 -0.34906585039886595 0.0" xyz="0.042 0.0 0.001"/>
    <parent link="middle_pp"/>
    <child link="middle_mp"/>
    <axis xyz="0.0 1.0 0.0"/>
    <limit effort="100.0" lower="0.0" upper="1.8151424220741028" velocity="100.0"/>
  </joint>
  <joint name="middle_mp2dp" type="revolute">
    <origin rpy="0.0 -0.3490658503988655 0.0" xyz="0.0315 0.0 0.0"/>
    <parent link="middle_mp"/>
    <child link="middle_dp"/>
    <axis xyz="0.0 1.0 0.0"/>
    <limit effort="100.0" lower="0.0" upper="1.8151424220741028" velocity="100.0"/>
  </joint>
  <joint name="ring_base2mcp" type="revolute">
    <origin rpy="-1.892140724241469 -1.1468495109844863 0.18502954434130636" xyz="0.019774239928720398 0.02008608404750523 0.1945985871955586"/>
    <parent link="base_link"/>
    <child link="ring_mcp"/>
    <axis xyz="0.0 0.0 -1.0"/>
    <limit effort="100.0" lower="0.0" upper="0.6283185307179586" velocity="100.0"/>
  </joint>
  <joint name="ring_mcp2pp" type="revolute">
    <origin rpy="0.0 -0.3490658503988653 0.0" xyz="0.009000000000000001 0.0 -0.0001499999999999796"/>
    <parent link="ring_mcp"/>
    <child link="ring_pp"/>
    <axis xyz="0.0 1.0 0.0"/>
    <limit effort="100.0" lower="0.0" upper="1.8151424220741028" velocity="100.0"/>
  </joint>
  <joint name="ring_pp2mp" type="revolute">
    <origin rpy="0.0 -0.34906585039886506 0.0" xyz="0.039 0.0 0.001"/>
    <parent link="ring_pp"/>
    <child link="ring_mp"/>
    <axis xyz="0.0 1.0 0.0"/>
    <limit effort="100.0" lower="0.0" upper="1.8151424220741028" velocity="100.0"/>
  </joint>
  <joint name="ring_mp2dp" type="revolute">
    <origin rpy="0.0 -0.34906585039886573 0.0" xyz="0.029 0.0 0.0"/>
    <parent link="ring_mp"/>
    <child link="ring_dp"/>
    <axis xyz="0.0 1.0 0.0"/>
    <limit effort="100.0" lower="0.0" upper="1.8151424220741028" velocity="100.0"/>
  </joint>
  <joint name="pinky_base2mcp" type="revolute">
    <origin rpy="-1.8115905887375803 -1.0082865765577846 -0.0012025167416593874" xyz="0.03955441908569687 0.013471938811980269 0.1812866151335743"/>
    <parent link="base_link"/>
    <child link="pinky_mcp"/>
    <axis xyz="0.0 0.0 -1.0"/>
    <limit effort="100.0" lower="0.0" upper="0.6283185307179586" velocity="100.0"/>
  </joint>
  <joint name="pinky_mcp2pp" type="revolute">
    <origin rpy="0.0 -0.34906585039886573 0.0" xyz="0.009000000000000001 0.0 -0.00014999999999991688"/>
    <parent link="pinky_mcp"/>
    <child link="pinky_pp"/>
    <axis xyz="0.0 1.0 0.0"/>
    <limit effort="100.0" lower="0.0" upper="1.8151424220741028" velocity="100.0"/>
  </joint>
  <joint name="pinky_pp2mp" type="revolute">
    <origin rpy="0.0 -0.34906585039886595 0.0" xyz="0.035500000000000004 0.0 0.001"/>
    <parent link="pinky_pp"/>
    <child link="pinky_mp"/>
    <axis xyz="0.0 1.0 0.0"/>
    <limit effort="100.0" lower="0.0" upper="1.8151424220741028" velocity="100.0"/>
  </joint>
  <joint name="pinky_mp2dp" type="revolute">
    <origin rpy="0.0 -0.34906585039886595 0.0" xyz="0.025 0.0 0.0"/>
    <parent link="pinky_mp"/>
    <child link="pinky_dp"/>
    <axis xyz="0.0 1.0 0.0"/>
    <limit effort="100.0" lower="0.0" upper="1.8151424220741028" velocity="100.0"/>
  </joint>
  <joint name="thumb_fingertip_offset" type="fixed">
    <origin rpy="-1.5707963267948966 0.0 1.4660765716752369" xyz="-0.0017901394116628922 0.00018815123388177924 -0.027"/>
    <parent link="thumb_dp"/>
    <child link="thumb_fingertip"/>
  </joint>
  <joint name="index_fingertip_offset" type="fixed">
    <origin rpy="3.141592653589793 0.0 1.5707963267948966" xyz="0.019 0.0 -0.005"/>
    <parent link="index_dp"/>
    <child link="index_fingertip"/>
  </joint>
  <joint name="middle_fingertip_offset" type="fixed">
    <origin rpy="3.141592653589793 0.0 1.5707963267948966" xyz="0.019 0.0 -0.005"/>
    <parent link="middle_dp"/>
    <child link="middle_fingertip"/>
  </joint>
  <joint name="ring_fingertip_offset" type="fixed">
    <origin rpy="3.141592653589793 0.0 1.5707963267948966" xyz="0.019 0.0 -0.005"/>
    <parent link="ring_dp"/>
    <child link="ring_fingertip"/>
  </joint>
  <joint name="pinky_fingertip_offset" type="fixed">
    <origin rpy="3.141592653589793 0.0 1.5707963267948966" xyz="0.019 0.0 -0.005"/>
    <parent link="pinky_dp"/>
    <child link="pinky_fingertip"/>
  </joint>
</robot>
