<?xml version="1.0" ?>
<!-- =================================================================================== -->
<!-- |    This document was autogenerated by xacro from simplified.xacro               | -->
<!-- |    EDITING THIS FILE BY HAND IS RECOMMENDED                                     | -->
<!-- =================================================================================== -->
<robot name="p50_autoconverted">
  <material name="silver_default">
    <color rgba="0.700 0.700 0.700 1.000"/>
  </material>
  <material name="Steel_Satin">
    <color rgba="0.6274509803921569 0.6274509803921569 0.6274509803921569 1.0"/>
  </material>
  <link name="root"/>
  <link name="base_link">
    <inertial>
      <origin rpy="0.0 0.0 0.0" xyz="-0.00025743985489043707 0.002783420515116142 0.05479188623862443"/>
      <mass value="11.839727556266766"/>
      <inertia ixx="0.025854110200000006" ixy="1.1251800000000001e-05" ixz="0.00026008170000000003" iyy="0.0314024074" iyz="-0.00035490340000000003" izz="0.027059390900000004"/>
    </inertial>
    <visual>
      <origin rpy="0.0 0.0 0.0" xyz="0.0 0.0 0.0"/>
      <geometry>
        <mesh filename="meshes/visual/base_link.stl" scale="0.001 0.001 0.001"/>
      </geometry>
      <material name="Steel_Satin"/>
    </visual>
    <!-- <collision>
      <origin rpy="0.0 0.0 0.0" xyz="0.0 0.0 0.0"/>
      <geometry>
        <mesh filename="meshes/visual/base_link.stl" scale="0.001 0.001 0.001"/>
      </geometry>
    </collision> -->
  </link>
  <link name="index_mcp">
    <inertial>
      <origin rpy="1.7017348928028146 -0.10749161153413689 1.762782544514273" xyz="0.0037575958450508295 0.0 3.1689745901815615e-05"/>
      <mass value="0.0026395511835507687"/>
      <inertia ixx="1.1820000000000003e-07" ixy="9e-10" ixz="1.04e-08" iyy="1.138e-07" iyz="-7.100000000000001e-09" izz="6.74e-08"/>
    </inertial>
    <visual>
      <origin rpy="1.7017348928028146 -0.10749161153413689 1.762782544514273" xyz="-0.19142570945292872 -0.0638459650901201 0.0027879270241161574"/>
      <geometry>
        <mesh filename="meshes/visual/index_mcp.stl" scale="0.001 0.001 0.001"/>
      </geometry>
      <material name="Steel_Satin"/>
    </visual>
    <!-- <collision>
      <origin rpy="1.7017348928028146 -0.10749161153413689 1.762782544514273" xyz="-0.19142570945292872 -0.0638459650901201 0.0027879270241161574"/>
      <geometry>
        <mesh filename="meshes/visual/index_mcp.stl" scale="0.001 0.001 0.001"/>
      </geometry>
    </collision> -->
  </link>
  <link name="middle_mcp">
    <inertial>
      <origin rpy="1.710422666954546 0.0 1.8849555921538765" xyz="0.0037575958450506877 0.0 3.168974590181506e-05"/>
      <mass value="0.0026395511835507687"/>
      <inertia ixx="1.15e-07" ixy="2.2000000000000003e-09" ixz="1.63e-08" iyy="1.1399999999999999e-07" iyz="-5.9e-09" izz="7.040000000000001e-08"/>
    </inertial>
    <visual>
      <origin rpy="1.710422666954546 0.0 1.8849555921538765" xyz="-0.19275971829860722 -0.06552295023217906 0.005739211794064878"/>
      <geometry>
        <mesh filename="meshes/visual/middle_mcp.stl" scale="0.001 0.001 0.001"/>
      </geometry>
      <material name="Steel_Satin"/>
    </visual>
    <!-- <collision>
      <origin rpy="1.710422666954546 0.0 1.8849555921538765" xyz="-0.19275971829860722 -0.06552295023217906 0.005739211794064878"/>
      <geometry>
        <mesh filename="meshes/visual/middle_mcp.stl" scale="0.001 0.001 0.001"/>
      </geometry>
    </collision> -->
  </link>
  <link name="pinky_mcp">
    <inertial>
      <origin rpy="1.7010466700342677 0.20431604263360326 2.1467549799530254" xyz="0.0037575958450507584 0.0 -0.00011831025409819008"/>
      <mass value="0.0026395511835507687"/>
      <inertia ixx="1.042e-07" ixy="9e-10" ixz="2.5099999999999996e-08" iyy="1.151e-07" iyz="1e-09" izz="8.01e-08"/>
    </inertial>
    <visual>
      <origin rpy="1.7010466700342677 0.20431604263360326 2.1467549799530254" xyz="-0.17443999513816405 -0.06463563158133116 0.001950706904977398"/>
      <geometry>
        <mesh filename="meshes/visual/pinky_mcp.stl" scale="0.001 0.001 0.001"/>
      </geometry>
      <material name="Steel_Satin"/>
    </visual>
    <!-- <collision>
      <origin rpy="1.7010466700342677 0.20431604263360326 2.1467549799530254" xyz="-0.17443999513816405 -0.06463563158133116 0.001950706904977398"/>
      <geometry>
        <mesh filename="meshes/visual/pinky_mcp.stl" scale="0.001 0.001 0.001"/>
      </geometry>
    </collision> -->
  </link>
  <link name="ring_mcp">
    <inertial>
      <origin rpy="1.7018668462741051 0.10862308449673885 2.00712863979348" xyz="0.003757595845050581 0.0 -0.00011831025409819729"/>
      <mass value="0.0026395511835507687"/>
      <inertia ixx="1.104e-07" ixy="2.2000000000000003e-09" ixz="2.12e-08" iyy="1.147e-07" iyz="-2.7e-09" izz="7.43e-08"/>
    </inertial>
    <visual>
      <origin rpy="1.7018668462741051 0.10862308449673885 2.00712863979348" xyz="-0.18579322370454734 -0.06428672495618938 0.0033431266067439026"/>
      <geometry>
        <mesh filename="meshes/visual/ring_mcp.stl" scale="0.001 0.001 0.001"/>
      </geometry>
      <material name="Steel_Satin"/>
    </visual>
    <!-- <collision>
      <origin rpy="1.7018668462741051 0.10862308449673885 2.00712863979348" xyz="-0.18579322370454734 -0.06428672495618938 0.0033431266067439026"/>
      <geometry>
        <mesh filename="meshes/visual/ring_mcp.stl" scale="0.001 0.001 0.001"/>
      </geometry>
    </collision> -->
  </link>
  <link name="thumb_cmc">
    <inertial>
      <origin rpy="-1.3936916939156758 -1.1603495754713762 0.9074649550610439" xyz="-6.285710729230232e-06 -0.018793316757115052 0.0032730901278382562"/>
      <mass value="0.13646098534521342"/>
      <inertia ixx="1.92542e-05" ixy="-1.1488e-06" ixz="-1.3239e-06" iyy="1.46583e-05" iyz="-3.821e-06" izz="1.97712e-05"/>
    </inertial>
    <visual>
      <origin rpy="-1.3936916939156758 -1.1603495754713762 0.9074649550610439" xyz="0.12438495858597794 -0.09398871280060712 -0.028859361053456926"/>
      <geometry>
        <mesh filename="meshes/visual/thumb_cmc.stl" scale="0.001 0.001 0.001"/>
      </geometry>
      <material name="Steel_Satin"/>
    </visual>
    <!-- <collision>
      <origin rpy="-1.3936916939156758 -1.1603495754713762 0.9074649550610439" xyz="0.12438495858597794 -0.09398871280060712 -0.028859361053456926"/>
      <geometry>
        <mesh filename="meshes/visual/thumb_cmc.stl" scale="0.001 0.001 0.001"/>
      </geometry>
    </collision> -->
  </link>
  <link name="ring_pp">
    <inertial>
      <origin rpy="2.017319625112362 -0.041832556602295234 2.017779554511588" xyz="0.018561009678868458 -4.811339149313199e-10 0.0015141649774916565"/>
      <mass value="0.011897317640220903"/>
      <inertia ixx="1.9203e-06" ixy="2.7180000000000004e-07" ixz="5.256000000000001e-07" iyy="2.0527000000000003e-06" iyz="-5.463000000000001e-07" izz="1.2427e-06"/>
    </inertial>
    <visual>
      <origin rpy="2.017319625112362 -0.041832556602295234 2.017779554511588" xyz="-0.18185103523156887 -0.06428672495618931 0.06990567158612668"/>
      <geometry>
        <mesh filename="meshes/visual/ring_pp.stl" scale="0.001 0.001 0.001"/>
      </geometry>
      <material name="Steel_Satin"/>
    </visual>
    <!-- <collision>
      <origin rpy="2.017319625112362 -0.041832556602295234 2.017779554511588" xyz="-0.18185103523156887 -0.06428672495618931 0.06990567158612668"/>
      <geometry>
        <mesh filename="meshes/visual/ring_pp.stl" scale="0.001 0.001 0.001"/>
      </geometry>
    </collision> -->
  </link>
  <link name="pinky_pp">
    <inertial>
      <origin rpy="1.9919857950196116 0.008258409274978673 2.177986893068568" xyz="0.016832793550349338 -5.251937906791682e-10 0.0015430211276084816"/>
      <mass value="0.010734968037856127"/>
      <inertia ixx="1.3951e-06" ixy="2.167e-07" ixz="4.893e-07" iyy="1.74e-06" iyz="-3.312e-07" izz="1.1441e-06"/>
    </inertial>
    <visual>
      <origin rpy="1.9919857950196116 0.008258409274978673 2.177986893068568" xyz="-0.1716587257116102 -0.06463563158133112 0.06471419220585613"/>
      <geometry>
        <mesh filename="meshes/visual/pinky_pp.stl" scale="0.001 0.001 0.001"/>
      </geometry>
      <material name="Steel_Satin"/>
    </visual>
    <!-- <collision>
      <origin rpy="1.9919857950196116 0.008258409274978673 2.177986893068568" xyz="-0.1716587257116102 -0.06463563158133112 0.06471419220585613"/>
      <geometry>
        <mesh filename="meshes/visual/pinky_pp.stl" scale="0.001 0.001 0.001"/>
      </geometry>
    </collision> -->
  </link>
  <link name="middle_pp">
    <inertial>
      <origin rpy="2.0436691263374858 -0.10588779879323673 1.8671309257691981" xyz="0.020018862469634725 -4.5057832132044953e-10 0.0014936913701924404"/>
      <mass value="0.012870595232919467"/>
      <inertia ixx="2.4711e-06" ixy="2.674e-07" ixz="4.5450000000000005e-07" iyy="2.3213e-06" iyz="-7.877000000000001e-07" izz="1.3277000000000002e-06"/>
    </inertial>
    <visual>
      <origin rpy="2.0436691263374858 -0.10588779879323673 1.8671309257691981" xyz="-0.18762919241666257 -0.06552295023217913 0.07439898274184653"/>
      <geometry>
        <mesh filename="meshes/visual/middle_pp.stl" scale="0.001 0.001 0.001"/>
      </geometry>
      <material name="Steel_Satin"/>
    </visual>
    <!-- <collision>
      <origin rpy="2.0436691263374858 -0.10588779879323673 1.8671309257691981" xyz="-0.18762919241666257 -0.06552295023217913 0.07439898274184653"/>
      <geometry>
        <mesh filename="meshes/visual/middle_pp.stl" scale="0.001 0.001 0.001"/>
      </geometry>
    </collision> -->
  </link>
  <link name="thumb_mp">
    <inertial>
      <origin rpy="0.6950622920666284 -1.1678650691046832 -1.1058638873720976" xyz="0.0011454097605115266 -0.00033109920687998787 0.017558791398614746"/>
      <mass value="0.1355419083343085"/>
      <inertia ixx="1.89377e-05" ixy="-3.6814e-06" ixz="-5.1552e-06" iyy="3.06259e-05" iyz="5.782e-07" izz="2.40837e-05"/>
    </inertial>
    <visual>
      <origin rpy="0.6950622920666284 -1.1678650691046832 -1.1058638873720976" xyz="0.12851644713633703 -0.033521944510523684 -0.06873471100954592"/>
      <geometry>
        <mesh filename="meshes/visual/thumb_mp.stl" scale="0.001 0.001 0.001"/>
      </geometry>
      <material name="Steel_Satin"/>
    </visual>
    <!-- <collision>
      <origin rpy="0.6950622920666284 -1.1678650691046832 -1.1058638873720976" xyz="0.12851644713633703 -0.033521944510523684 -0.06873471100954592"/>
      <geometry>
        <mesh filename="meshes/visual/thumb_mp.stl" scale="0.001 0.001 0.001"/>
      </geometry>
    </collision> -->
  </link>
  <link name="index_pp">
    <inertial>
      <origin rpy="2.049122246280331 -0.16646628811745767 1.7148519263181665" xyz="0.01856100967886853 -4.811338971677514e-10 0.0015141649774916034"/>
      <mass value="0.011897317640220903"/>
      <inertia ixx="2.1764e-06" ixy="1.207e-07" ixz="1.766e-07" iyy="1.9517e-06" iyz="-6.791000000000001e-07" izz="1.0876000000000002e-06"/>
    </inertial>
    <visual>
      <origin rpy="2.049122246280331 -0.16646628811745767 1.7148519263181665" xyz="-0.18738503298832798 -0.06384596509012005 0.07116942432509113"/>
      <geometry>
        <mesh filename="meshes/visual/index_pp.stl" scale="0.001 0.001 0.001"/>
      </geometry>
      <material name="Steel_Satin"/>
    </visual>
    <!-- <collision>
      <origin rpy="2.049122246280331 -0.16646628811745767 1.7148519263181665" xyz="-0.18738503298832798 -0.06384596509012005 0.07116942432509113"/>
      <geometry>
        <mesh filename="meshes/visual/index_pp.stl" scale="0.001 0.001 0.001"/>
      </geometry>
    </collision> -->
  </link>
  <link name="pinky_mp">
    <inertial>
      <origin rpy="2.28198369074538 -0.18849108567474793 2.151578092030236" xyz="0.012255335613894722 0.0 0.0006277124921955491"/>
      <mass value="0.005213101795055971"/>
      <inertia ixx="3.716e-07" ixy="9.810000000000001e-08" ixz="8.86e-08" iyy="3.434e-07" iyz="-1.035e-07" izz="3.6340000000000004e-07"/>
    </inertial>
    <visual>
      <origin rpy="2.28198369074538 -0.18849108567474793 2.151578092030236" xyz="-0.17287398873248602 -0.06463563158133112 0.13072421331422582"/>
      <geometry>
        <mesh filename="meshes/visual/pinky_mp.stl" scale="0.001 0.001 0.001"/>
      </geometry>
      <material name="Steel_Satin"/>
    </visual>
    <!-- <collision>
      <origin rpy="2.28198369074538 -0.18849108567474793 2.151578092030236" xyz="-0.17287398873248602 -0.06463563158133112 0.13072421331422582"/>
      <geometry>
        <mesh filename="meshes/visual/pinky_mp.stl" scale="0.001 0.001 0.001"/>
      </geometry>
    </collision> -->
  </link>
  <link name="middle_mp">
    <inertial>
      <origin rpy="2.383961950832267 -0.19996221125455294 1.8147421851065413" xyz="0.01546234793396053 0.0 0.0005268185283266469"/>
      <mass value="0.006850263254868857"/>
      <inertia ixx="7.458000000000001e-07" ixy="9.640000000000002e-08" ixz="8.12e-08" iyy="4.819000000000001e-07" iyz="-2.581e-07" izz="5.603000000000001e-07"/>
    </inertial>
    <visual>
      <origin rpy="2.383961950832267 -0.19996221125455294 1.8147421851065413" xyz="-0.19067692703364025 -0.06552295023217913 0.14751029175780983"/>
      <geometry>
        <mesh filename="meshes/visual/middle_mp.stl" scale="0.001 0.001 0.001"/>
      </geometry>
      <material name="Steel_Satin"/>
    </visual>
    <!-- <collision>
      <origin rpy="2.383961950832267 -0.19996221125455294 1.8147421851065413" xyz="-0.19067692703364025 -0.06552295023217913 0.14751029175780983"/>
      <geometry>
        <mesh filename="meshes/visual/middle_mp.stl" scale="0.001 0.001 0.001"/>
      </geometry>
    </collision> -->
  </link>
  <link name="index_mp">
    <inertial>
      <origin rpy="2.402168281060521 -0.20557147641561535 1.6488813450951116" xyz="0.014231615723840357 0.0 0.0005568085980096172"/>
      <mass value="0.006227568575151113"/>
      <inertia ixx="6.363000000000001e-07" ixy="2.54e-08" ixz="2.13e-08" iyy="3.9870000000000004e-07" iyz="-2.159e-07" izz="4.5170000000000005e-07"/>
    </inertial>
    <visual>
      <origin rpy="2.402168281060521 -0.20557147641561535 1.6488813450951116" xyz="-0.18873298839075897 -0.06384596509012003 0.14336593167253767"/>
      <geometry>
        <mesh filename="meshes/visual/index_mp.stl" scale="0.001 0.001 0.001"/>
      </geometry>
      <material name="Steel_Satin"/>
    </visual>
    <!-- <collision>
      <origin rpy="2.402168281060521 -0.20557147641561535 1.6488813450951116" xyz="-0.18873298839075897 -0.06384596509012003 0.14336593167253767"/>
      <geometry>
        <mesh filename="meshes/visual/index_mp.stl" scale="0.001 0.001 0.001"/>
      </geometry>
    </collision> -->
  </link>
  <link name="thumb_pp">
    <inertial>
      <origin rpy="2.0518472638487895 -1.1253353688103003 -2.3731843774931276" xyz="0.0004743124953415645 -4.9851246354823966e-05 0.014037341494746515"/>
      <mass value="0.08561101056611906"/>
      <inertia ixx="7.876200000000001e-06" ixy="-1.8488000000000002e-06" ixz="1.3738e-06" iyy="1.11943e-05" iyz="2.56e-07" izz="1.28189e-05"/>
    </inertial>
    <visual>
      <origin rpy="2.0518472638487895 -1.1253353688103003 -2.3731843774931276" xyz="0.16260298040794055 -0.03710458352289372 -0.024178686024923027"/>
      <geometry>
        <mesh filename="meshes/visual/thumb_pp.stl" scale="0.001 0.001 0.001"/>
      </geometry>
      <material name="Steel_Satin"/>
    </visual>
    <!-- <collision>
      <origin rpy="2.0518472638487895 -1.1253353688103003 -2.3731843774931276" xyz="0.16260298040794055 -0.03710458352289372 -0.024178686024923027"/>
      <geometry>
        <mesh filename="meshes/visual/thumb_pp.stl" scale="0.001 0.001 0.001"/>
      </geometry>
    </collision> -->
  </link>
  <link name="ring_mp">
    <inertial>
      <origin rpy="2.3366775745781356 -0.18811365872715968 1.9807334102973713" xyz="0.014231615723840463 0.0 0.0005568085980097414"/>
      <mass value="0.006227568575151113"/>
      <inertia ixx="5.723e-07" ixy="1.1750000000000001e-07" ixz="1.0300000000000001e-07" iyy="4.35e-07" iyz="-1.842e-07" izz="4.794e-07"/>
    </inertial>
    <visual>
      <origin rpy="2.3366775745781356 -0.18811365872715968 1.9807334102973713" xyz="-0.18396496042819585 -0.06428672495618933 0.14028565384330433"/>
      <geometry>
        <mesh filename="meshes/visual/ring_mp.stl" scale="0.001 0.001 0.001"/>
      </geometry>
      <material name="Steel_Satin"/>
    </visual>
    <!-- <collision>
      <origin rpy="2.3366775745781356 -0.18811365872715968 1.9807334102973713" xyz="-0.18396496042819585 -0.06428672495618933 0.14028565384330433"/>
      <geometry>
        <mesh filename="meshes/visual/ring_mp.stl" scale="0.001 0.001 0.001"/>
      </geometry>
    </collision> -->
  </link>
  <link name="pinky_dp">
    <inertial>
      <origin rpy="2.5935418325013315 -0.36870925476651006 2.064899017996019" xyz="0.01089306086427829 1.1616753781140688e-10 0.0008705848933307437"/>
      <mass value="0.004531952355822714"/>
      <inertia ixx="3.0200000000000003e-07" ixy="6.46e-08" ixz="5.3e-09" iyy="2.064e-07" iyz="-4.8000000000000006e-08" izz="3.3800000000000004e-07"/>
    </inertial>
    <visual>
      <origin rpy="2.5935418325013315 -0.36870925476651006 2.064899017996019" xyz="-0.14123041288352414 -0.0646356315813311 0.1905174685961275"/>
      <geometry>
        <mesh filename="meshes/visual/pinky_dp.stl" scale="0.001 0.001 0.001"/>
      </geometry>
      <material name="Steel_Satin"/>
    </visual>
    <!-- <collision>
      <origin rpy="2.5935418325013315 -0.36870925476651006 2.064899017996019" xyz="-0.14123041288352414 -0.0646356315813311 0.1905174685961275"/>
      <geometry>
        <mesh filename="meshes/visual/pinky_dp.stl" scale="0.001 0.001 0.001"/>
      </geometry>
    </collision> -->
  </link>
  <link name="thumb_dp">
    <inertial>
      <origin rpy="2.575873468038568 -0.6985501890607833 -2.8004979807671586" xyz="0.0008304358993063232 -9.483275416703574e-05 0.011994918369585755"/>
      <mass value="0.05558786060995699"/>
      <inertia ixx="4.2789e-06" ixy="-6.912e-07" ixz="1.4033000000000002e-06" iyy="4.6252e-06" iyz="8.619000000000001e-07" izz="3.8414999999999996e-06"/>
    </inertial>
    <visual>
      <origin rpy="2.575873468038568 -0.6985501890607833 -2.8004979807671586" xyz="0.16797776915732932 -0.037669496584112686 0.03500921083680618"/>
      <geometry>
        <mesh filename="meshes/visual/thumb_dp.stl" scale="0.001 0.001 0.001"/>
      </geometry>
      <material name="Steel_Satin"/>
    </visual>
    <!-- <collision>
      <origin rpy="2.575873468038568 -0.6985501890607833 -2.8004979807671586" xyz="0.16797776915732932 -0.037669496584112686 0.03500921083680618"/>
      <geometry>
        <mesh filename="meshes/visual/thumb_dp.stl" scale="0.001 0.001 0.001"/>
      </geometry>
    </collision> -->
  </link>
  <link name="ring_dp">
    <inertial>
      <origin rpy="2.6728699610002273 -0.3148104789350532 1.896165719050475" xyz="0.010929353372684431 2.959357979115396e-07 0.0009004211113699867"/>
      <mass value="0.004517050419432207"/>
      <inertia ixx="3.1389999999999997e-07" ixy="4.5700000000000006e-08" ixz="2e-09" iyy="1.8980000000000002e-07" iyz="-5.140000000000001e-08" izz="3.374e-07"/>
    </inertial>
    <visual>
      <origin rpy="2.6728699610002273 -0.3148104789350532 1.896165719050475" xyz="-0.15214108236631646 -0.06428672495618931 0.2046637000076761"/>
      <geometry>
        <mesh filename="meshes/visual/ring_dp.stl" scale="0.001 0.001 0.001"/>
      </geometry>
      <material name="Steel_Satin"/>
    </visual>
    <!-- <collision>
      <origin rpy="2.6728699610002273 -0.3148104789350532 1.896165719050475" xyz="-0.15214108236631646 -0.06428672495618931 0.2046637000076761"/>
      <geometry>
        <mesh filename="meshes/visual/ring_dp.stl" scale="0.001 0.001 0.001"/>
      </geometry>
    </collision> -->
  </link>
  <link name="index_dp">
    <inertial>
      <origin rpy="2.75907306776212 -0.21969714881519486 1.5727867236837585" xyz="0.010929353372684397 2.95935797893776e-07 0.0009004211113699512"/>
      <mass value="0.004517050419432207"/>
      <inertia ixx="3.2420000000000006e-07" ixy="-2e-10" ixz="-7.9e-09" iyy="1.783e-07" iyz="-5.5800000000000003e-08" izz="3.385e-07"/>
    </inertial>
    <visual>
      <origin rpy="2.75907306776212 -0.21969714881519486 1.5727867236837585" xyz="-0.15556804599380084 -0.06384596509012007 0.2091889759609138"/>
      <geometry>
        <mesh filename="meshes/visual/index_dp.stl" scale="0.001 0.001 0.001"/>
      </geometry>
      <material name="Steel_Satin"/>
    </visual>
    <!-- <collision>
      <origin rpy="2.75907306776212 -0.21969714881519486 1.5727867236837585" xyz="-0.15556804599380084 -0.06384596509012007 0.2091889759609138"/>
      <geometry>
        <mesh filename="meshes/visual/index_dp.stl" scale="0.001 0.001 0.001"/>
      </geometry>
    </collision> -->
  </link>
  <link name="middle_dp">
    <inertial>
      <origin rpy="2.7356230218691495 -0.2709185204562192 1.7318491121837347" xyz="0.010952231529227845 7.231160470411169e-10 0.0009189466335334373"/>
      <mass value="0.0045069103448089716"/>
      <inertia ixx="3.214e-07" ixy="2.3300000000000003e-08" ixz="-2.9000000000000003e-09" iyy="1.7840000000000004e-07" iyz="-5.2200000000000004e-08" izz="3.3769999999999996e-07"/>
    </inertial>
    <visual>
      <origin rpy="2.7356230218691495 -0.2709185204562192 1.7318491121837347" xyz="-0.1583265277133833 -0.065522950232179 0.21460331708249222"/>
      <geometry>
        <mesh filename="meshes/visual/middle_dp.stl" scale="0.001 0.001 0.001"/>
      </geometry>
      <material name="Steel_Satin"/>
    </visual>
    <!-- <collision>
      <origin rpy="2.7356230218691495 -0.2709185204562192 1.7318491121837347" xyz="-0.1583265277133833 -0.065522950232179 0.21460331708249222"/>
      <geometry>
        <mesh filename="meshes/visual/middle_dp.stl" scale="0.001 0.001 0.001"/>
      </geometry>
    </collision> -->
  </link>
  <link name="index_fingertip">
    <inertial>
      <origin rpy="-0.38251958582767304 0.21969714881519486 -0.0019903968888615453" xyz="0.0 0.0 0.0"/>
      <mass value="1e-4"/>
      <inertia ixx="1e-8" ixy="0.0" ixz="0.0" iyy="1e-8" iyz="0.0" izz="1e-8"/>
    </inertial>
    <visual>
      <origin rpy="-0.38251958582767304 0.21969714881519486 -0.0019903968888615453" xyz="-0.06384596509012004 -0.17456804599380057 -0.21418897596091363"/>
      <geometry>
        <mesh filename="meshes/visual/index_fingertip.stl" scale="0.001 0.001 0.001"/>
      </geometry>
      <material name="Steel_Satin"/>
    </visual>
    <!-- <collision>
      <origin rpy="-0.38251958582767304 0.21969714881519486 -0.0019903968888615453" xyz="-0.06384596509012004 -0.17456804599380057 -0.21418897596091363"/>
      <geometry>
        <mesh filename="meshes/visual/index_fingertip.stl" scale="0.001 0.001 0.001"/>
      </geometry>
    </collision> -->
  </link>
  <link name="thumb_fingertip">
    <inertial>
      <origin rpy="0.07336084956936173 -0.7627723998296027 1.0964553254573675" xyz="0.0 0.0 0.0"/>
      <mass value="1e-4"/>
      <inertia ixx="1e-8" ixy="0.0" ixz="0.0" iyy="1e-8" iyz="0.0" izz="1e-8"/>
    </inertial>
    <visual>
      <origin rpy="0.07336084956936173 -0.7627723998296027 1.0964553254573675" xyz="0.019904681067256277 0.008009210836806151 -0.17279510395208492"/>
      <geometry>
        <mesh filename="meshes/visual/thumb_fingertip.stl" scale="0.001 0.001 0.001"/>
      </geometry>
      <material name="Steel_Satin"/>
    </visual>
    <!-- <collision>
      <origin rpy="0.07336084956936173 -0.7627723998296027 1.0964553254573675" xyz="0.019904681067256277 0.008009210836806151 -0.17279510395208492"/>
      <geometry>
        <mesh filename="meshes/visual/thumb_fingertip.stl" scale="0.001 0.001 0.001"/>
      </geometry>
    </collision> -->
  </link>
  <link name="ring_fingertip">
    <inertial>
      <origin rpy="-0.468722692589566 0.3148104789350532 -0.3253693922555786" xyz="0.0 0.0 0.0"/>
      <mass value="1e-4"/>
      <inertia ixx="1e-8" ixy="0.0" ixz="0.0" iyy="1e-8" iyz="0.0" izz="1e-8"/>
    </inertial>
    <visual>
      <origin rpy="-0.468722692589566 0.3148104789350532 -0.3253693922555786" xyz="-0.06428672495618924 -0.1711410823663162 -0.20966370000767579"/>
      <geometry>
        <mesh filename="meshes/visual/ring_fingertip.stl" scale="0.001 0.001 0.001"/>
      </geometry>
      <material name="Steel_Satin"/>
    </visual>
    <!-- <collision>
      <origin rpy="-0.468722692589566 0.3148104789350532 -0.3253693922555786" xyz="-0.06428672495618924 -0.1711410823663162 -0.20966370000767579"/>
      <geometry>
        <mesh filename="meshes/visual/ring_fingertip.stl" scale="0.001 0.001 0.001"/>
      </geometry>
    </collision> -->
  </link>
  <link name="middle_fingertip">
    <inertial>
      <origin rpy="-0.4059696317206436 0.27091852045621945 -0.16105278538883716" xyz="0.0 0.0 0.0"/>
      <mass value="1e-4"/>
      <inertia ixx="1e-8" ixy="0.0" ixz="0.0" iyy="1e-8" iyz="0.0" izz="1e-8"/>
    </inertial>
    <visual>
      <origin rpy="-0.4059696317206436 0.27091852045621945 -0.16105278538883716" xyz="-0.065522950232179 -0.17732652771338359 -0.2196033170824925"/>
      <geometry>
        <mesh filename="meshes/visual/middle_fingertip.stl" scale="0.001 0.001 0.001"/>
      </geometry>
      <material name="Steel_Satin"/>
    </visual>
    <!-- <collision>
      <origin rpy="-0.4059696317206436 0.27091852045621945 -0.16105278538883716" xyz="-0.065522950232179 -0.17732652771338359 -0.2196033170824925"/>
      <geometry>
        <mesh filename="meshes/visual/middle_fingertip.stl" scale="0.001 0.001 0.001"/>
      </geometry>
    </collision> -->
  </link>
  <link name="pinky_fingertip">
    <inertial>
      <origin rpy="-0.5480508210884618 0.36870925476651006 -0.4941026912011226" xyz="0.0 0.0 0.0"/>
      <mass value="1e-4"/>
      <inertia ixx="1e-8" ixy="0.0" ixz="0.0" iyy="1e-8" iyz="0.0" izz="1e-8"/>
    </inertial>
    <visual>
      <origin rpy="-0.5480508210884618 0.36870925476651006 -0.4941026912011226" xyz="-0.06463563158133105 -0.16023041288352427 -0.19551746859612754"/>
      <geometry>
        <mesh filename="meshes/visual/pinky_fingertip.stl" scale="0.001 0.001 0.001"/>
      </geometry>
      <material name="Steel_Satin"/>
    </visual>
    <!-- <collision>
      <origin rpy="-0.5480508210884618 0.36870925476651006 -0.4941026912011226" xyz="-0.06463563158133105 -0.16023041288352427 -0.19551746859612754"/>
      <geometry>
        <mesh filename="meshes/visual/pinky_fingertip.stl" scale="0.001 0.001 0.001"/>
      </geometry>
    </collision> -->
  </link>
  <joint name="root2base" type="fixed">
    <parent link="root"/>
    <child link="base_link"/>
  </joint>
  <joint name="thumb_base2cmc" type="revolute">
    <origin rpy="1.4250210672946975 1.065626150328479 1.038308733801324" xyz="0.02545227277276528 0.013843049223912985 0.15588107831179898"/>
    <parent link="base_link"/>
    <child link="thumb_cmc"/>
    <axis xyz="0.0 -1.0 0.0"/>
    <limit effort="100.0" lower="0.0" upper="1.4835298641951802" velocity="3.14"/>
  </joint>
  <joint name="thumb_cmc2mcp" type="revolute">
    <origin rpy="-0.6954281481356811 0.06724025795674438 -0.024378546945008406" xyz="0.0 -0.021158280580912462 0.011000000000000001"/>
    <parent link="thumb_cmc"/>
    <child link="thumb_mp"/>
    <axis xyz="-0.9945218953682721 0.10452846326765308 0.0"/>
    <limit effort="100.0" lower="-1.2217304763960306" upper="0.0" velocity="3.14"/>
  </joint>
  <joint name="thumb_mcp2pp" type="revolute">
    <origin rpy="0.06027643041747295 0.5204388675801157 0.016053508633057777" xyz="0.0 0.0 0.035"/>
    <parent link="thumb_mp"/>
    <child link="thumb_pp"/>
    <axis xyz="-0.1045284632676538 -0.994521895368276 0.0"/>
    <limit effort="100.0" lower="0.0" upper="1.7453292519943295" velocity="3.14"/>
  </joint>
  <joint name="thumb_pp2dp_actuated" type="revolute">
    <origin rpy="0.06027643041747299 0.520438867580117 0.016053508633057646" xyz="0.0 0.0 0.031"/>
    <parent link="thumb_pp"/>
    <child link="thumb_dp"/>
    <axis xyz="-0.10452846326765311 -0.99452189536827 0.0"/>
    <limit effort="100.0" lower="0.0" upper="2.0943951023931953" velocity="3.14"/>
  </joint>
  <joint name="index_base2mcp" type="revolute">
    <origin rpy="2.1398948280438876 -1.3275096116627072 2.4775640048362435" xyz="0.02569717283048402 0.020595546697329645 0.19910640572240776"/>
    <parent link="base_link"/>
    <child link="index_mcp"/>
    <axis xyz="0.0 0.0 1.0"/>
    <limit effort="100.0" lower="0.0" upper="0.6283185307179586" velocity="3.14"/>
  </joint>
  <joint name="index_mcp2pp" type="revolute">
    <origin rpy="0.0 -0.34906585039886684 0.0" xyz="0.009000000000000001 0.0 0.0"/>
    <parent link="index_mcp"/>
    <child link="index_pp"/>
    <axis xyz="0.0 1.0 0.0"/>
    <limit effort="100.0" lower="0.0" upper="1.8151424220741028" velocity="3.14"/>
  </joint>
  <joint name="index_pp2mp" type="revolute">
    <origin rpy="0.0 -0.3490658503988653 0.0" xyz="0.039 0.0 0.001"/>
    <parent link="index_pp"/>
    <child link="index_mp"/>
    <axis xyz="0.0 1.0 0.0"/>
    <limit effort="100.0" lower="0.0" upper="1.8151424220741028" velocity="3.14"/>
  </joint>
  <joint name="index_mp2dp" type="revolute">
    <origin rpy="0.0 -0.34906585039886573 0.0" xyz="0.029 0.0 0.0"/>
    <parent link="index_mp"/>
    <child link="index_dp"/>
    <axis xyz="0.0 1.0 0.0"/>
    <limit effort="100.0" lower="0.0" upper="1.8151424220741028" velocity="3.14"/>
    <mimic joint="index_pp2mp" multiplier="1.0" offset="0.0"/>
  </joint>
  <joint name="middle_base2mcp" type="revolute">
    <origin rpy="1.9976345056314648 -1.2279478135732096 2.736904207080983" xyz="0.0027499999999997483 0.022648540210313265 0.20239067588218101"/>
    <parent link="base_link"/>
    <child link="middle_mcp"/>
    <axis xyz="0.0 0.0 1.0"/>
    <limit effort="100.0" lower="0.0" upper="0.6283185307179586" velocity="3.14"/>
  </joint>
  <joint name="middle_mcp2pp" type="revolute">
    <origin rpy="0.0 -0.3490658503988664 0.0" xyz="0.009000000000000001 0.0 0.0"/>
    <parent link="middle_mcp"/>
    <child link="middle_pp"/>
    <axis xyz="0.0 1.0 0.0"/>
    <limit effort="100.0" lower="0.0" upper="1.8151424220741028" velocity="3.14"/>
  </joint>
  <joint name="middle_pp2mp" type="revolute">
    <origin rpy="0.0 -0.3490658503988664 0.0" xyz="0.042 0.0 0.001"/>
    <parent link="middle_pp"/>
    <child link="middle_mp"/>
    <axis xyz="0.0 1.0 0.0"/>
    <limit effort="100.0" lower="0.0" upper="1.8151424220741028" velocity="3.14"/>
  </joint>
  <joint name="middle_mp2dp" type="revolute">
    <origin rpy="0.0 -0.34906585039886573 0.0" xyz="0.0315 0.0 0.0"/>
    <parent link="middle_mp"/>
    <child link="middle_dp"/>
    <axis xyz="0.0 1.0 0.0"/>
    <limit effort="100.0" lower="0.0" upper="1.8151424220741028" velocity="3.14"/>
    <mimic joint="middle_pp2mp" multiplier="1.0" offset="0.0"/>
  </joint>
  <joint name="ring_base2mcp" type="revolute">
    <origin rpy="1.8804023355185873 -1.1302572287916681 2.969489968772729" xyz="-0.01977423992872009 0.02008608404750541 0.1945985871955589"/>
    <parent link="base_link"/>
    <child link="ring_mcp"/>
    <axis xyz="0.0 0.0 1.0"/>
    <limit effort="100.0" lower="0.0" upper="0.6283185307179586" velocity="3.14"/>
  </joint>
  <joint name="ring_mcp2pp" type="revolute">
    <origin rpy="0.0 -0.3490658503988653 0.0" xyz="0.009000000000000001 0.0 -0.00015000000000004344"/>
    <parent link="ring_mcp"/>
    <child link="ring_pp"/>
    <axis xyz="0.0 1.0 0.0"/>
    <limit effort="100.0" lower="0.0" upper="1.8151424220741028" velocity="3.14"/>
  </joint>
  <joint name="ring_pp2mp" type="revolute">
    <origin rpy="0.0 -0.3490658503988653 0.0" xyz="0.039 0.0 0.001"/>
    <parent link="ring_pp"/>
    <child link="ring_mp"/>
    <axis xyz="0.0 1.0 0.0"/>
    <limit effort="100.0" lower="0.0" upper="1.8151424220741028" velocity="3.14"/>
  </joint>
  <joint name="ring_mp2dp" type="revolute">
    <origin rpy="0.0 -0.34906585039886595 0.0" xyz="0.029 0.0 0.0"/>
    <parent link="ring_mp"/>
    <child link="ring_dp"/>
    <axis xyz="0.0 1.0 0.0"/>
    <limit effort="100.0" lower="0.0" upper="1.8151424220741028" velocity="3.14"/>
    <mimic joint="ring_pp2mp" multiplier="1.0" offset="0.0"/>
  </joint>
  <joint name="pinky_base2mcp" type="revolute">
    <origin rpy="1.8115905887375807 -1.0082865765577846 -3.140390136848134" xyz="-0.03955441908569702 0.013471938811980349 0.1812866151335743"/>
    <parent link="base_link"/>
    <child link="pinky_mcp"/>
    <axis xyz="0.0 0.0 1.0"/>
    <limit effort="100.0" lower="0.0" upper="0.6283185307179586" velocity="3.14"/>
  </joint>
  <joint name="pinky_mcp2pp" type="revolute">
    <origin rpy="0.0 -0.34906585039886573 0.0" xyz="0.009000000000000001 0.0 -0.0001499999999999918"/>
    <parent link="pinky_mcp"/>
    <child link="pinky_pp"/>
    <axis xyz="0.0 1.0 0.0"/>
    <limit effort="100.0" lower="0.0" upper="1.8151424220741028" velocity="3.14"/>
  </joint>
  <joint name="pinky_pp2mp" type="revolute">
    <origin rpy="0.0 -0.34906585039886573 0.0" xyz="0.035500000000000004 0.0 0.001"/>
    <parent link="pinky_pp"/>
    <child link="pinky_mp"/>
    <axis xyz="0.0 1.0 0.0"/>
    <limit effort="100.0" lower="0.0" upper="1.8151424220741028" velocity="3.14"/>
  </joint>
  <joint name="pinky_mp2dp" type="revolute">
    <origin rpy="0.0 -0.34906585039886573 0.0" xyz="0.025 0.0 0.0"/>
    <parent link="pinky_mp"/>
    <child link="pinky_dp"/>
    <axis xyz="0.0 1.0 0.0"/>
    <limit effort="100.0" lower="0.0" upper="1.8151424220741028" velocity="3.14"/>
    <mimic joint="pinky_pp2mp" multiplier="1.0" offset="0.0"/>
  </joint>
  <joint name="thumb_fingertip_offset" type="fixed">
    <origin rpy="1.5707963267948966 0.0 -1.675516081914556" xyz="-0.0017901394116629987 0.00018815123388174815 0.027"/>
    <parent link="thumb_dp"/>
    <child link="thumb_fingertip"/>
  </joint>
  <joint name="index_fingertip_offset" type="fixed">
    <origin rpy="3.141592653589793 0.0 1.5707963267948966" xyz="0.019 0.0 -0.005"/>
    <parent link="index_dp"/>
    <child link="index_fingertip"/>
  </joint>
  <joint name="middle_fingertip_offset" type="fixed">
    <origin rpy="3.141592653589793 0.0 1.5707963267948966" xyz="0.019 0.0 -0.005"/>
    <parent link="middle_dp"/>
    <child link="middle_fingertip"/>
  </joint>
  <joint name="ring_fingertip_offset" type="fixed">
    <origin rpy="3.141592653589793 0.0 1.5707963267948966" xyz="0.019 0.0 -0.005"/>
    <parent link="ring_dp"/>
    <child link="ring_fingertip"/>
  </joint>
  <joint name="pinky_fingertip_offset" type="fixed">
    <origin rpy="3.141592653589793 0.0 1.5707963267948966" xyz="0.019 0.0 -0.005"/>
    <parent link="pinky_dp"/>
    <child link="pinky_fingertip"/>
  </joint>
</robot>
